<?xml version="1.0" ?>
<!-- =================================================================================== -->
<!-- |    This document was autogenerated by xacro from marco.xacro                    | -->
<!-- |    EDITING THIS FILE BY HAND IS NOT RECOMMENDED                                 | -->
<!-- =================================================================================== -->
<robot name="marco">
  <gazebo>
    <plugin filename="libgazebo_ros_control.so" name="gazebo_ros_control">
      <robotNamespace>/marco</robotNamespace>
    </plugin>
  </gazebo>
  <gazebo reference="">
    <self_collide>1</self_collide>
  </gazebo>
  <link name="world"/>
  <link name="link0">
    <visual>
      <geometry>
        <cylinder length="0.01" radius="1.0"/>
      </geometry>
      <origin rpy="0 0 0" xyz="0 0 0.005"/>
    </visual>
    <inertial>
      <mass value="1.0"/>
      <inertia ixx="1.0" ixy="0.0" ixz="0.0" iyy="1.0" iyz="0.0" izz="1.0"/>
    </inertial>
  </link>
  <link name="link1">
    <visual>
      <geometry>
        <mesh filename="package://marco_description/models/marco/meshes/link1.stl" scale="0.1 0.1 0.1"/>
      </geometry>
      <origin rpy="0 0 1.570796326794895" xyz="0 0 0"/>
    </visual>
    <collision>
      <geometry>
        <cylinder length="0.03" radius="0.05"/>
      </geometry>
      <origin rpy="0 0 0" xyz="0 0 0.065"/>
    </collision>
    <inertial>
      <origin rpy="0 0 0" xyz="0 0 0"/>
      <mass value="0.065"/>
      <inertia ixx="9.154166666666668e-05" ixy="0" ixz="0" iyy="0" iyz="0" izz="0.0003661666666666667"/>
    </inertial>
  </link>
  <link name="link2">
    <visual>
      <geometry>
        <mesh filename="package://marco_description/models/marco/meshes/link2.stl" scale="0.1 0.1 0.1"/>
      </geometry>
      <origin rpy="0 0 1.570796326794895" xyz="0 0 0"/>
    </visual>
    <collision>
      <geometry>
        <cylinder length="0.13999999999999999" radius="0.05"/>
      </geometry>
      <origin rpy="0 0 0" xyz="0 0 0.12"/>
    </collision>
    <inertial>
      <origin rpy="0 0 0" xyz="0 0 0"/>
      <mass value="0.12"/>
      <inertia ixx="0.000576" ixy="0" ixz="0" iyy="0" iyz="0" izz="0.002304"/>
    </inertial>
  </link>
  <link name="link3">
    <visual>
      <geometry>
        <mesh filename="package://marco_description/models/marco/meshes/link3.stl" scale="0.1 0.1 0.1"/>
      </geometry>
      <origin rpy="0 0 1.570796326794895" xyz="0 0 0"/>
    </visual>
    <collision>
      <geometry>
        <cylinder length="0.23" radius="0.05"/>
      </geometry>
      <origin rpy="0 0 0" xyz="0 0 0.165"/>
    </collision>
    <inertial>
      <origin rpy="0 0 0" xyz="0 0 0"/>
      <mass value="0.165"/>
      <inertia ixx="0.0014973750000000002" ixy="0" ixz="0" iyy="0" iyz="0" izz="0.005989500000000001"/>
    </inertial>
  </link>
  <link name="link4">
    <visual>
      <geometry>
        <mesh filename="package://marco_description/models/marco/meshes/link4.stl" scale="0.1 0.1 0.1"/>
      </geometry>
      <origin rpy="0 0 1.570796326794895" xyz="0 0 0"/>
    </visual>
    <collision>
      <geometry>
        <cylinder length="0.26" radius="0.05"/>
      </geometry>
      <origin rpy="0 0 0" xyz="0 0 0.18"/>
    </collision>
    <inertial>
      <origin rpy="0 0 0" xyz="0 0 0"/>
      <mass value="0.18"/>
      <inertia ixx="0.0019439999999999998" ixy="0" ixz="0" iyy="0" iyz="0" izz="0.007775999999999999"/>
    </inertial>
  </link>
  <link name="link5">
    <visual>
      <geometry>
        <mesh filename="package://marco_description/models/marco/meshes/link5.stl" scale="0.1 0.1 0.1"/>
      </geometry>
      <origin rpy="0 0 1.570796326794895" xyz="0 0 0"/>
    </visual>
    <collision>
      <geometry>
        <cylinder length="0.13" radius="0.05"/>
      </geometry>
      <origin rpy="0 0 0" xyz="0 0 0.115"/>
    </collision>
    <inertial>
      <origin rpy="0 0 0" xyz="0 0 0"/>
      <mass value="0.115"/>
      <inertia ixx="0.0005069583333333333" ixy="0" ixz="0" iyy="0" iyz="0" izz="0.0020278333333333333"/>
    </inertial>
  </link>
  <link name="link6">
    <visual>
      <geometry>
        <mesh filename="package://marco_description/models/marco/meshes/link6.stl" scale="0.1 0.1 0.1"/>
      </geometry>
      <origin rpy="0 0 1.570796326794895" xyz="0 0 0"/>
    </visual>
    <collision>
      <geometry>
        <cylinder length="0.21" radius="0.05"/>
      </geometry>
      <origin rpy="0 0 0" xyz="0 0 0.155"/>
    </collision>
    <inertial>
      <origin rpy="0 0 0" xyz="0 0 0"/>
      <mass value="0.155"/>
      <inertia ixx="0.004965166666666667" ixy="0" ixz="0" iyy="0" iyz="0" izz="0.004965166666666667"/>
    </inertial>
  </link>
  <link name="gripper_tip"/>
  <link name="gripper_a">
    <visual>
      <geometry>
        <mesh filename="package://marco_description/models/marco/meshes/gripper_a.stl" scale="0.1 0.1 0.1"/>
      </geometry>
      <origin rpy="0 1.570796326794895 0" xyz="0 0 0"/>
    </visual>
    <inertial>
      <mass value="1.0"/>
      <inertia ixx="1.0" ixy="0.0" ixz="0.0" iyy="1.0" iyz="0.0" izz="1.0"/>
    </inertial>
  </link>
  <link name="gripper_b">
    <visual>
      <geometry>
        <mesh filename="package://marco_description/models/marco/meshes/gripper_b.stl" scale="0.1 0.1 0.1"/>
      </geometry>
      <origin rpy="0 -1.570796326794895 0" xyz="0 0 0"/>
    </visual>
    <inertial>
      <mass value="1.0"/>
      <inertia ixx="1.0" ixy="0.0" ixz="0.0" iyy="1.0" iyz="0.0" izz="1.0"/>
    </inertial>
  </link>
  <joint name="fixed" type="fixed">
    <origin rpy="0 0 0" xyz="0 0 0"/>
    <parent link="world"/>
    <child link="link0"/>
  </joint>
  <joint name="joint1" type="continuous">
    <origin rpy="0 0 0" xyz="0 0 0"/>
    <axis xyz="0 0 1"/>
    <dynamics damping="0.5"/>
    <parent link="link0"/>
    <child link="link1"/>
  </joint>
  <joint name="joint2" type="continuous">
    <origin rpy="0 0 0" xyz="0 0 0.13"/>
    <axis xyz="0 -1 0"/>
    <dynamics damping="0.5"/>
    <parent link="link1"/>
    <child link="link2"/>
  </joint>
  <joint name="joint3" type="continuous">
    <origin rpy="0 0 0" xyz="0 0 0.24"/>
    <axis xyz="0 -1 0"/>
    <dynamics damping="0.5"/>
    <parent link="link2"/>
    <child link="link3"/>
  </joint>
  <joint name="joint4" type="continuous">
    <origin rpy="0 0 0" xyz="0 0 0.33"/>
    <axis xyz="0 0 1"/>
    <dynamics damping="0.5"/>
    <parent link="link3"/>
    <child link="link4"/>
  </joint>
  <joint name="joint5" type="continuous">
    <origin rpy="0 0 0" xyz="0 0 0.36"/>
    <axis xyz="0 -1 0"/>
    <dynamics damping="0.5"/>
    <parent link="link4"/>
    <child link="link5"/>
  </joint>
  <joint name="joint6" type="continuous">
    <origin rpy="0 0 0" xyz="0 0 0.23"/>
    <axis xyz="0 0 1"/>
    <dynamics damping="0.5"/>
    <parent link="link5"/>
    <child link="link6"/>
  </joint>
  <joint name="gripper_fixed" type="fixed">
    <origin rpy="0 0 0" xyz="0 0 0.31"/>
    <parent link="link6"/>
    <child link="gripper_tip"/>
  </joint>
  <joint name="joint_gripper_a" type="fixed">
    <origin rpy="0 0 0" xyz="-0.1 0 0.17"/>
    <parent link="link6"/>
    <child link="gripper_a"/>
  </joint>
  <joint name="joint_gripper_b" type="fixed">
    <origin rpy="0 0 0" xyz="0.1 0 0.17"/>
    <parent link="link6"/>
    <child link="gripper_b"/>
  </joint>
  <transmission name="tran1">
    <type>transmission_interface/SimpleTransmission</type>
    <joint name="joint1">
      <hardwareInterface>hardware_interface/EffortJointInterface</hardwareInterface>
    </joint>
    <actuator name="motor1">
      <hardwareInterface>hardware_interface/EffortJointInterface</hardwareInterface>
      <mechanicalReduction>1</mechanicalReduction>
    </actuator>
  </transmission>
  <transmission name="tran2">
    <type>transmission_interface/SimpleTransmission</type>
    <joint name="joint2">
      <hardwareInterface>hardware_interface/EffortJointInterface</hardwareInterface>
    </joint>
    <actuator name="motor2">
      <hardwareInterface>hardware_interface/EffortJointInterface</hardwareInterface>
      <mechanicalReduction>1</mechanicalReduction>
    </actuator>
  </transmission>
  <transmission name="tran3">
    <type>transmission_interface/SimpleTransmission</type>
    <joint name="joint3">
      <hardwareInterface>hardware_interface/EffortJointInterface</hardwareInterface>
    </joint>
    <actuator name="motor3">
      <hardwareInterface>hardware_interface/EffortJointInterface</hardwareInterface>
      <mechanicalReduction>1</mechanicalReduction>
    </actuator>
  </transmission>
  <transmission name="tran4">
    <type>transmission_interface/SimpleTransmission</type>
    <joint name="joint4">
      <hardwareInterface>hardware_interface/EffortJointInterface</hardwareInterface>
    </joint>
    <actuator name="motor4">
      <hardwareInterface>hardware_interface/EffortJointInterface</hardwareInterface>
      <mechanicalReduction>1</mechanicalReduction>
    </actuator>
  </transmission>
  <transmission name="tran5">
    <type>transmission_interface/SimpleTransmission</type>
    <joint name="joint5">
      <hardwareInterface>hardware_interface/EffortJointInterface</hardwareInterface>
    </joint>
    <actuator name="motor5">
      <hardwareInterface>hardware_interface/EffortJointInterface</hardwareInterface>
      <mechanicalReduction>1</mechanicalReduction>
    </actuator>
  </transmission>
  <transmission name="tran6">
    <type>transmission_interface/SimpleTransmission</type>
    <joint name="joint6">
      <hardwareInterface>hardware_interface/EffortJointInterface</hardwareInterface>
    </joint>
    <actuator name="motor6">
      <hardwareInterface>hardware_interface/EffortJointInterface</hardwareInterface>
      <mechanicalReduction>1</mechanicalReduction>
    </actuator>
  </transmission>
</robot>

