<?xml version="1.0"?>
<robot xmlns:xacro="http://www.ros.org/wiki/xacro" name="marco">
  <xacro:property name="L1" value="0.13"/>
  <xacro:property name="L2" value="0.24"/>
  <xacro:property name="L3" value="0.33"/>
  <xacro:property name="L4" value="0.36"/>
  <xacro:property name="L5" value="0.23"/>
  <xacro:property name="L6" value="0.31"/>
  <xacro:property name="rho" value="0.5"/>
  <xacro:property name="PI" value="3.14159265358979"/>
  
  <gazebo>
    <plugin name="gazebo_ros_control" filename="libgazebo_ros_control.so">
      <robotNamespace>/marco</robotNamespace>
    </plugin>
  </gazebo>

  <gazebo reference="">
    <self_collide>1</self_collide>
  </gazebo>

  <link name="world"/>
  
  <link name="link0">
    <visual>
      <geometry>
        <cylinder length="0.01" radius="1.0"/>
      </geometry>
      <origin xyz="0 0 0.005" rpy="0 0 0"/>
    </visual>
    <inertial>
      <mass value="1.0" />
      <inertia ixx="1.0" ixy="0.0" ixz="0.0" iyy="1.0" iyz="0.0" izz="1.0" />
    </inertial>
  </link>

  <link name="link1">
    <visual>
      <geometry>
        <mesh filename="package://marco_description/models/marco/meshes/link1.stl" scale="0.1 0.1 0.1"/>
      </geometry>
      <origin xyz="0 0 0" rpy="0 0 ${PI / 2}"/>
    </visual>
    <collision>
      <geometry>
        <cylinder length="${L1-0.1}" radius="0.05"/>
      </geometry>
      <origin xyz="0 0 ${L1/2}" rpy="0 0 0"/>
    </collision>
    <inertial>
      <origin xyz="0 0 0" rpy="0 0 0"/>
      <mass value="${rho*L1}"/>
      <inertia ixx="${(rho*L1*L1*L1)/12}"  ixy="0"  ixz="0" iyy="0" iyz="0" izz="${(rho*L1*L1*L1)/3}" />
    </inertial>
  </link>

  <link name="link2">
    <visual>
      <geometry>
        <mesh filename="package://marco_description/models/marco/meshes/link2.stl" scale="0.1 0.1 0.1"/>
      </geometry>
      <origin xyz="0 0 0" rpy="0 0 ${PI / 2}"/>
    </visual>
    <collision>
      <geometry>
        <cylinder length="${L2-0.1}" radius="0.05"/>
      </geometry>
      <origin xyz="0 0 ${L2/2}" rpy="0 0 0"/>
    </collision>
    <inertial>
      <origin xyz="0 0 0" rpy="0 0 0"/>
      <mass value="${rho*L2}"/>
      <inertia ixx="${(rho*L2*L2*L2)/12}"  ixy="0"  ixz="0" iyy="0" iyz="0" izz="${(rho*L2*L2*L2)/3}" />
    </inertial>
  </link>

  <link name="link3">
    <visual>
      <geometry>
        <mesh filename="package://marco_description/models/marco/meshes/link3.stl" scale="0.1 0.1 0.1"/>
      </geometry>
      <origin xyz="0 0 0" rpy="0 0 ${PI / 2}"/>
    </visual>
    <collision>
      <geometry>
        <cylinder length="${L3-0.1}" radius="0.05"/>
      </geometry>
      <origin xyz="0 0 ${L3/2}" rpy="0 0 0"/>
    </collision>
    <inertial>
      <origin xyz="0 0 0" rpy="0 0 0"/>
      <mass value="${rho*L3}"/>
      <inertia ixx="${(rho*L3*L3*L3)/12}"  ixy="0"  ixz="0" iyy="0" iyz="0" izz="${(rho*L3*L3*L3)/3}" />
   </inertial>
  </link>

  <link name="link4">
    <visual>
      <geometry>
        <mesh filename="package://marco_description/models/marco/meshes/link4.stl" scale="0.1 0.1 0.1"/>
      </geometry>
      <origin xyz="0 0 0" rpy="0 0 ${PI / 2}"/>
    </visual>
    <collision>
      <geometry>
        <cylinder length="${L4-0.1}" radius="0.05"/>
      </geometry>
      <origin xyz="0 0 ${L4/2}" rpy="0 0 0"/>
    </collision>
    <inertial>
      <origin xyz="0 0 0" rpy="0 0 0"/>
      <mass value="${rho*L4}"/>
      <inertia ixx="${(rho*L4*L4*L4)/12}"  ixy="0"  ixz="0" iyy="0" iyz="0" izz="${(rho*L4*L4*L4)/3}" />
    </inertial>
  </link>

  <link name="link5">
    <visual>
      <geometry>
        <mesh filename="package://marco_description/models/marco/meshes/link5.stl" scale="0.1 0.1 0.1"/>
      </geometry>
      <origin xyz="0 0 0" rpy="0 0 ${PI / 2}"/>
    </visual>
    <collision>
      <geometry>
        <cylinder length="${L5-0.1}" radius="0.05"/>
      </geometry>
      <origin xyz="0 0 ${L5/2}" rpy="0 0 0"/>
    </collision>
    <inertial>
      <origin xyz="0 0 0" rpy="0 0 0"/>
      <mass value="${rho*L5}"/>
      <inertia ixx="${(rho*L5*L5*L5)/12}"  ixy="0"  ixz="0" iyy="0" iyz="0" izz="${(rho*L5*L5*L5)/3}" />
    </inertial>
  </link>

  <link name="link6">
    <visual>
      <geometry>
        <mesh filename="package://marco_description/models/marco/meshes/link6.stl" scale="0.1 0.1 0.1"/>
      </geometry>
      <origin xyz="0 0 0" rpy="0 0 ${PI / 2}"/>
    </visual>
    <collision>
      <geometry>
        <cylinder length="${L6-0.1}" radius="0.05"/>
      </geometry>
      <origin xyz="0 0 ${L6/2}" rpy="0 0 0"/>
    </collision>
    <inertial>
      <origin xyz="0 0 0" rpy="0 0 0"/>
      <mass value="${rho*L6}"/>
      <inertia ixx="${(rho*L6*L6*L6)/3}"  ixy="0"  ixz="0" iyy="0" iyz="0" izz="${(rho*L6*L6*L6)/3}" />
    </inertial>
  </link>


  <link name="gripper_tip"/>

  <link name="gripper_a">
    <visual>
      <geometry>
        <mesh filename="package://marco_description/models/marco/meshes/gripper_a.stl" scale="0.1 0.1 0.1"/>
      </geometry>
      <origin xyz="0 0 0" rpy="0 0 ${PI / 2}"/>
    </visual>
    <inertial>
      <mass value="1.0" />
      <inertia ixx="1.0" ixy="0.0" ixz="0.0" iyy="1.0" iyz="0.0" izz="1.0" />
    </inertial>
  </link>

  <link name="gripper_b">
    <visual>
      <geometry>
        <mesh filename="package://marco_description/models/marco/meshes/gripper_b.stl" scale="0.1 0.1 0.1"/>
      </geometry>
      <origin xyz="0 0 0" rpy="0 0 ${PI / 2}"/>
    </visual>
    <inertial>
      <mass value="1.0" />
      <inertia ixx="1.0" ixy="0.0" ixz="0.0" iyy="1.0" iyz="0.0" izz="1.0" />
    </inertial>
  </link>

  <joint name="fixed" type="fixed">
    <origin xyz="0 0 0" rpy="0 0 0"/>
    <parent link="world"/>
    <child link="link0"/>
  </joint>

  <joint name="joint1" type="continuous">
    <origin xyz="0 0 0" rpy="0 0 0"/>
    <axis xyz="0 0 1" />
    <dynamics damping="0.5"/>
    <parent link="link0"/>
    <child link="link1"/>
  </joint>

  <joint name="joint2" type="continuous">
    <origin xyz="0 0 ${L1}" rpy="0 0 0"/>
    <axis xyz="0 -1 0" />
    <dynamics damping="0.5"/>
    <parent link="link1"/>
    <child link="link2"/>
  </joint>

  <joint name="joint3" type="continuous">
    <origin xyz="0 0 ${L2}" rpy="0 0 0"/>
    <axis xyz="0 -1 0" />
    <dynamics damping="0.5"/>
    <parent link="link2"/>
    <child link="link3"/>
  </joint>

  <joint name="joint4" type="continuous">
    <origin xyz="0 0 ${L3}" rpy="0 0 0"/>
    <axis xyz="0 0 1" />
    <dynamics damping="0.5"/>
    <parent link="link3"/>
    <child link="link4"/>
  </joint>

  <joint name="joint5" type="continuous">
    <origin xyz="0 0 ${L4}" rpy="0 0 0"/>
    <axis xyz="0 -1 0" />
    <dynamics damping="0.5"/>
    <parent link="link4"/>
    <child link="link5" />
  </joint>

  <joint name="joint6" type="continuous">
    <origin xyz="0 0 ${L5}" rpy="0 0 0"/>
    <axis xyz="0 0 1" />
    <dynamics damping="0.5"/>
    <parent link="link5"/>
    <child link="link6"/>
  </joint>

  <joint name="gripper_fixed" type="fixed">
    <origin xyz="0 0 ${L6}" rpy="0 0 0"/>
    <parent link="link6"/>
    <child link="gripper_tip"/>
  </joint>

  <joint name="joint_gripper_a" type="fixed">
    <origin xyz="0 -0.1 0.17" rpy="0 0 0"/>
    <parent link="link6"/>
    <child link="gripper_a"/>
  </joint>

  <joint name="joint_gripper_b" type="fixed">
    <origin xyz="0 0.1 0.17" rpy="0 0 0"/>
    <parent link="link6"/>
    <child link="gripper_b"/>
  </joint>

  <transmission name="tran1">
    <type>transmission_interface/SimpleTransmission</type>
    <joint name="joint1">
      <hardwareInterface>hardware_interface/EffortJointInterface</hardwareInterface>
    </joint>
    <actuator name="motor1">
      <hardwareInterface>hardware_interface/EffortJointInterface</hardwareInterface>
      <mechanicalReduction>1</mechanicalReduction>
    </actuator>
  </transmission>

  <transmission name="tran2">
    <type>transmission_interface/SimpleTransmission</type>
    <joint name="joint2">
      <hardwareInterface>hardware_interface/EffortJointInterface</hardwareInterface>
    </joint>
    <actuator name="motor2">
      <hardwareInterface>hardware_interface/EffortJointInterface</hardwareInterface>
      <mechanicalReduction>1</mechanicalReduction>
    </actuator>
  </transmission>

  <transmission name="tran3">
    <type>transmission_interface/SimpleTransmission</type>
    <joint name="joint3">
      <hardwareInterface>hardware_interface/EffortJointInterface</hardwareInterface>
    </joint>
    <actuator name="motor3">
      <hardwareInterface>hardware_interface/EffortJointInterface</hardwareInterface>
      <mechanicalReduction>1</mechanicalReduction>
    </actuator>
  </transmission>

  <transmission name="tran4">
    <type>transmission_interface/SimpleTransmission</type>
    <joint name="joint4">
      <hardwareInterface>hardware_interface/EffortJointInterface</hardwareInterface>
    </joint>
    <actuator name="motor4">
      <hardwareInterface>hardware_interface/EffortJointInterface</hardwareInterface>
      <mechanicalReduction>1</mechanicalReduction>
    </actuator>
  </transmission>

  <transmission name="tran5">
    <type>transmission_interface/SimpleTransmission</type>
    <joint name="joint5">
      <hardwareInterface>hardware_interface/EffortJointInterface</hardwareInterface>
    </joint>
    <actuator name="motor5">
      <hardwareInterface>hardware_interface/EffortJointInterface</hardwareInterface>
      <mechanicalReduction>1</mechanicalReduction>
    </actuator>
  </transmission>

  <transmission name="tran6">
    <type>transmission_interface/SimpleTransmission</type>
    <joint name="joint6">
      <hardwareInterface>hardware_interface/EffortJointInterface</hardwareInterface>
    </joint>
    <actuator name="motor6">
      <hardwareInterface>hardware_interface/EffortJointInterface</hardwareInterface>
      <mechanicalReduction>1</mechanicalReduction>
    </actuator>
  </transmission>
</robot>